<?xml version="1" ?>
<!-- =================================================================================== -->
<!-- |    This document was autogenerated by xacro from ./urdf.xacro                   | -->
<!-- |    EDITING THIS FILE BY HAND IS NOT RECOMMENDED                                 | -->
<!-- =================================================================================== -->
<robot name="sawyer" xmlns:xacro="http://www.ros.org/wiki/xacro">
  <material name="black">
    <color rgba="0 0 0 1"/>
  </material>
  <material name="darkgray">
    <color rgba="0.2 0.2 0.2 1"/>
  </material>
  <material name="darkred">
    <color rgba="0.5 0.1 0.1 1"/>
  </material>
  <material name="sawyer_red">
    <color rgba="0.5 0.1 0.1 1"/>
  </material>
  <material name="sawyer_gray">
    <color rgba="0.75294 0.75294 0.75294 1"/>
  </material>
  <link name="right_arm_base_link">
    <inertial>
      <origin rpy="0 0 0" xyz="-0.0006241 -2.8025e-05 0.065404"/>
      <mass value="2.0687"/>
      <inertia ixx="0.0067599" ixy="-4.2024e-05" ixz="-6.1904e-07" iyy="0.0067877" iyz="1.5888e-05" izz="0.0074031"/>
    </inertial>
    <visual>
      <origin rpy="0 0 0" xyz="0 0 0"/>
      <geometry>
        <mesh filename="package://sawyer_description/meshes/sawyer_pv/base.DAE"/>
      </geometry>
      <material name="sawyer_red"/>
    </visual>
    <collision>
      <origin rpy="0 0 0" xyz="0 0 0.12"/>
      <geometry>
        <cylinder length="0.24" radius="0.08"/>
      </geometry>
    </collision>
  </link>
  <link name="right_l0">
    <inertial>
      <origin rpy="0 0 0" xyz="0.024366 0.010969 0.14363"/>
      <mass value="5.3213"/>
      <inertia ixx="0.053314" ixy="0.0047093" ixz="0.011734" iyy="0.057902" iyz="0.0080179" izz="0.023659"/>
    </inertial>
    <visual>
      <origin rpy="0 0 0" xyz="0 0 0"/>
      <geometry>
        <mesh filename="package://sawyer_description/meshes/sawyer_mp3/l0.DAE"/>
      </geometry>
      <material name="sawyer_red"/>
    </visual>
    <collision>
      <origin rpy="0 0 0" xyz="0.081 0 0.237"/>
      <geometry>
        <sphere radius="0.07"/>
      </geometry>
    </collision>
  </link>
  <joint name="right_j0" type="revolute">
    <origin rpy="0 0 0" xyz="0 0 0.08"/>
    <parent link="right_arm_base_link"/>
    <child link="right_l0"/>
    <axis xyz="0 0 1"/>
    <limit effort="80" lower="-3.0503" upper="3.0503" velocity="1.74"/>
    <dynamics damping="0.1"/>
  </joint>
  
  <link name="right_l1">
    <inertial>
      <origin rpy="0 0 0" xyz="-0.0030849 -0.026811 0.092521"/>
      <mass value="4.505"/>
      <inertia ixx="0.022398" ixy="-0.00023986" ixz="-0.00029362" iyy="0.014613" iyz="-0.0060875" izz="0.017295"/>
    </inertial>
    <visual>
      <origin rpy="0 0 0" xyz="0 0 0"/>
      <geometry>
        <mesh filename="package://sawyer_description/meshes/sawyer_mp3/l1.DAE"/>
      </geometry>
      <material name="sawyer_red"/>
    </visual>
    <collision>
      <origin rpy="0 0 0" xyz="0 0 0.1225"/>
      <geometry>
        <sphere radius="0.07"/>
      </geometry>
    </collision>
  </link>
  <joint name="right_j1" type="revolute">
    <origin rpy="-1.5708 1.5708 0" xyz="0.081 0.05 0.237"/>
    <parent link="right_l0"/>
    <child link="right_l1"/>
    <axis xyz="0 0 1"/>
    <limit effort="80" lower="-3.8183" upper="2.2824" velocity="1.328"/>
    <dynamics damping="0.1"/>
  </joint>
  <link name="right_l2">
    <inertial>
      <origin rpy="0 0 0" xyz="-0.00016232 -0.015346 0.13445"/>
      <mass value="1.7251"/>
      <inertia ixx="0.025176" ixy="4.3031e-06" ixz="1.4564e-05" iyy="0.024982" iyz="-0.0033928" izz="0.0033798"/>
    </inertial>
    <visual>
      <origin rpy="0 0 0" xyz="0 0 0"/>
      <geometry>
        <mesh filename="package://sawyer_description/meshes/sawyer_pv/l2.DAE"/>
      </geometry>
      <material name="sawyer_red"/>
    </visual>
    <collision>
      <origin rpy="0 0 0" xyz="0 0 0.14"/>
      <geometry>
        <cylinder length="0.35" radius="0.06"/>
      </geometry>
    </collision>
  </link>
  <joint name="right_j2" type="revolute">
    <origin rpy="1.5708 0 0" xyz="0 -0.14 0.1425"/>
    <parent link="right_l1"/>
    <child link="right_l2"/>
    <axis xyz="0 0 1"/>
    <limit effort="40" lower="-3.0514" upper="3.0514" velocity="1.957"/>
    <dynamics damping="0.1"/>
  </joint>
  <link name="right_l3">
    <inertial>
      <origin rpy="0 0 0" xyz="-0.0046678 -0.028394 -0.083127"/>
      <mass value="2.4743"/>
      <inertia ixx="0.0099549" ixy="-1.7675e-05" ixz="0.00027521" iyy="0.0064248" iyz="0.0030853" izz="0.0067746"/>
    </inertial>
    <visual>
      <origin rpy="0 0 0" xyz="0 0 0"/>
      <geometry>
        <mesh filename="package://sawyer_description/meshes/sawyer_pv/l3.DAE"/>
      </geometry>
      <material name="sawyer_red"/>
    </visual>
    <collision>
      <origin rpy="0 0 0" xyz="0 -0.01 -0.12"/>
      <geometry>
        <sphere radius="0.06"/>
      </geometry>
    </collision>
  </link>
  <joint name="right_j3" type="revolute">
    <origin rpy="-1.5708 0 0" xyz="0 -0.042 0.26"/>
    <parent link="right_l2"/>
    <child link="right_l3"/>
    <axis xyz="0 0 1"/>
    <limit effort="40" lower="-3.0514" upper="3.0514" velocity="1.957"/>
    <dynamics damping="0.1"/>
  </joint>
  <link name="right_l4">
    <inertial>
      <origin rpy="0 0 0" xyz="-0.0027794 0.0076558 0.13273"/>
      <mass value="1.0433"/>
      <inertia ixx="0.012913" ixy="2.573e-05" ixz="0.00017705" iyy="0.012939" iyz="0.0011152" izz="0.0012405"/>
    </inertial>
    <visual>
      <origin rpy="0 0 0" xyz="0 0 0"/>
      <geometry>
        <mesh filename="package://sawyer_description/meshes/sawyer_pv/l4.DAE"/>
      </geometry>
      <material name="sawyer_red"/>
    </visual>
    <collision>
      <origin rpy="0 0 0" xyz="0 0 0.14"/>
      <geometry>
        <cylinder length="0.36" radius="0.045"/>
      </geometry>
    </collision>
  </link>
  <joint name="right_j4" type="revolute">
    <origin rpy="1.5708 0 0" xyz="0 -0.125 -0.1265"/>
    <parent link="right_l3"/>
    <child link="right_l4"/>
    <axis xyz="0 0 1"/>
    <limit effort="9" lower="-2.9842" upper="2.9842" velocity="3.485"/>
    <dynamics damping="0.1"/>
  </joint>
 
  <link name="right_l5">
    <inertial>
      <origin rpy="0 0 0" xyz="0.0062067 -0.024291 0.075564"/>
      <mass value="1.5343"/>
      <inertia ixx="0.0046072" ixy="0.00012002" ixz="5.3065e-05" iyy="0.0028725" iyz="-0.0011886" izz="0.003101"/>
    </inertial>
    <visual>
      <origin rpy="0 0 0" xyz="0 0 0"/>
      <geometry>
        <mesh filename="package://sawyer_description/meshes/sawyer_pv/l5.STL"/>
      </geometry>
      <material name="sawyer_red"/>
    </visual>
    <collision>
      <origin rpy="0 0 0" xyz="0.01 0 0.09"/>
      <geometry>
        <sphere radius="0.06"/>
      </geometry>
    </collision>
  </link>
  <joint name="right_j5" type="revolute">
    <origin rpy="-1.5708 0 0" xyz="0 0.031 0.275"/>
    <parent link="right_l4"/>
    <child link="right_l5"/>
    <axis xyz="0 0 1"/>
    <limit effort="9" lower="-2.9842" upper="2.9842" velocity="3.485"/>
    <dynamics damping="0.1"/>
  </joint>
  <link name="right_l6">
    <inertial>
      <origin rpy="0 0 0" xyz="-8.0726e-06 0.0085838 -0.0049566"/>
      <mass value="0.3292"/>
      <inertia ixx="0.00031105" ixy="1.4771e-06" ixz="-3.7074e-07" iyy="0.00021549" iyz="-8.4533e-06" izz="0.00035976"/>
    </inertial>
    <visual>
      <origin rpy="0 0 0" xyz="0 0 0"/>
      <geometry>
        <mesh filename="package://sawyer_description/meshes/sawyer_mp1/l6.STL"/>
      </geometry>
      <material name="sawyer_red"/>
    </visual>
    <collision>
      <origin rpy="0 0 0" xyz="0 0 -0.005"/>
      <geometry>
        <cylinder length="0.05" radius="0.065"/>
      </geometry>
    </collision>
  </link>
  <joint name="right_j6" type="revolute">
    <origin rpy="-1.5708 -0.17453 3.1416" xyz="0 -0.11 0.1053"/>
    <parent link="right_l5"/>
    <child link="right_l6"/>
    <axis xyz="0 0 1"/>
    <limit effort="9" lower="-4.7104" upper="4.7104" velocity="4.545"/>
    <dynamics damping="0.1"/>
  </joint>
</robot>




 <!--  <link name="right_hand">
    <collision>
      <origin rpy="0 0 0" xyz="0 0 0.02"/>
      <geometry>
        <cylinder length="0.04" radius="0.06"/>
      </geometry>
    </collision>
    <inertial>
      <origin rpy="0 0 0" xyz="1.0E-08 1.0E-08 1.0E-08"/>
      <mass value="1.0E-08"/>
      <inertia ixx="1.0E-08" ixy="1.0E-08" ixz="1.0E-08" iyy="1.0E-08" iyz="1.0E-08" izz="1.0E-08"/>
    </inertial>
  </link>
  <joint name="right_hand" type="fixed">
    <origin rpy="0 0 1.570796" xyz="0 0 0.0245"/>
    <axis xyz="0 0 1"/>
    <parent link="right_l6"/>
    <child link="right_hand"/>
  </joint> -->

